Failure # 1 (occurred at 2022-12-14_10-55-58)
[36mray::PPO.train()[39m (pid=915766, ip=128.36.108.32, repr=PPO)
  File "/home/accts/ahc49/.local/lib/python3.10/site-packages/ray/tune/trainable/trainable.py", line 355, in train
    raise skipped from exception_cause(skipped)
  File "/home/accts/ahc49/.local/lib/python3.10/site-packages/ray/tune/trainable/trainable.py", line 352, in train
    result = self.step()
  File "/home/accts/ahc49/.local/lib/python3.10/site-packages/ray/rllib/algorithms/algorithm.py", line 772, in step
    results, train_iter_ctx = self._run_one_training_iteration()
  File "/home/accts/ahc49/.local/lib/python3.10/site-packages/ray/rllib/algorithms/algorithm.py", line 2953, in _run_one_training_iteration
    num_recreated += self.try_recover_from_step_attempt(
  File "/home/accts/ahc49/.local/lib/python3.10/site-packages/ray/rllib/algorithms/algorithm.py", line 2617, in try_recover_from_step_attempt
    raise error
  File "/home/accts/ahc49/.local/lib/python3.10/site-packages/ray/rllib/algorithms/algorithm.py", line 2948, in _run_one_training_iteration
    results = self.training_step()
  File "/home/accts/ahc49/.local/lib/python3.10/site-packages/ray/rllib/algorithms/ppo/ppo.py", line 408, in training_step
    train_batch = synchronous_parallel_sample(
  File "/home/accts/ahc49/.local/lib/python3.10/site-packages/ray/rllib/execution/rollout_ops.py", line 100, in synchronous_parallel_sample
    sample_batches = ray.get(
ray.exceptions.RayTaskError(ValueError): [36mray::RolloutWorker.sample()[39m (pid=915960, ip=128.36.108.32, repr=<ray.rllib.evaluation.rollout_worker.RolloutWorker object at 0x7f026775cc70>)
  File "/home/accts/ahc49/.local/lib/python3.10/site-packages/ray/rllib/evaluation/rollout_worker.py", line 828, in sample
    batches = [self.input_reader.next()]
  File "/home/accts/ahc49/.local/lib/python3.10/site-packages/ray/rllib/evaluation/sampler.py", line 92, in next
    batches = [self.get_data()]
  File "/home/accts/ahc49/.local/lib/python3.10/site-packages/ray/rllib/evaluation/sampler.py", line 285, in get_data
    item = next(self._env_runner)
  File "/home/accts/ahc49/.local/lib/python3.10/site-packages/ray/rllib/evaluation/sampler.py", line 721, in _env_runner
    base_env.send_actions(actions_to_send)
  File "/home/accts/ahc49/.local/lib/python3.10/site-packages/ray/rllib/env/multi_agent_env.py", line 615, in send_actions
    raise e
  File "/home/accts/ahc49/.local/lib/python3.10/site-packages/ray/rllib/env/multi_agent_env.py", line 608, in send_actions
    obs, rewards, dones, infos = env.step(agent_dict)
  File "/home/accts/ahc49/.local/lib/python3.10/site-packages/ray/rllib/env/wrappers/pettingzoo_env.py", line 184, in step
    obss, rews, dones, infos = self.par_env.step(action_dict)
  File "/home/accts/ahc49/csec491/salary-negotation/environment/job_search_environment.py", line 725, in step
    self._update_action_masks()
  File "/home/accts/ahc49/csec491/salary-negotation/environment/job_search_environment.py", line 1057, in _update_action_masks
    offer_details = get_employer_offer_values_and_deadlines(
  File "/home/accts/ahc49/csec491/salary-negotation/environment/job_search_environment.py", line 924, in get_employer_offer_values_and_deadlines
    np.ones(
  File "/usr/lib64/python3.10/site-packages/numpy/core/numeric.py", line 204, in ones
    a = empty(shape, dtype, order)
ValueError: negative dimensions are not allowed
