Failure # 1 (occurred at 2022-12-14_11-17-24)
[36mray::PPO.train()[39m (pid=926726, ip=128.36.108.32, repr=PPO)
  File "/home/accts/ahc49/.local/lib/python3.10/site-packages/ray/tune/trainable/trainable.py", line 355, in train
    raise skipped from exception_cause(skipped)
  File "/home/accts/ahc49/.local/lib/python3.10/site-packages/ray/tune/trainable/trainable.py", line 352, in train
    result = self.step()
  File "/home/accts/ahc49/.local/lib/python3.10/site-packages/ray/rllib/algorithms/algorithm.py", line 772, in step
    results, train_iter_ctx = self._run_one_training_iteration()
  File "/home/accts/ahc49/.local/lib/python3.10/site-packages/ray/rllib/algorithms/algorithm.py", line 2953, in _run_one_training_iteration
    num_recreated += self.try_recover_from_step_attempt(
  File "/home/accts/ahc49/.local/lib/python3.10/site-packages/ray/rllib/algorithms/algorithm.py", line 2617, in try_recover_from_step_attempt
    raise error
  File "/home/accts/ahc49/.local/lib/python3.10/site-packages/ray/rllib/algorithms/algorithm.py", line 2948, in _run_one_training_iteration
    results = self.training_step()
  File "/home/accts/ahc49/.local/lib/python3.10/site-packages/ray/rllib/algorithms/ppo/ppo.py", line 408, in training_step
    train_batch = synchronous_parallel_sample(
  File "/home/accts/ahc49/.local/lib/python3.10/site-packages/ray/rllib/execution/rollout_ops.py", line 100, in synchronous_parallel_sample
    sample_batches = ray.get(
ray.exceptions.RayTaskError(ValueError): [36mray::RolloutWorker.sample()[39m (pid=926951, ip=128.36.108.32, repr=<ray.rllib.evaluation.rollout_worker.RolloutWorker object at 0x7f5fba658c40>)
  File "/home/accts/ahc49/.local/lib/python3.10/site-packages/ray/rllib/evaluation/rollout_worker.py", line 828, in sample
    batches = [self.input_reader.next()]
  File "/home/accts/ahc49/.local/lib/python3.10/site-packages/ray/rllib/evaluation/sampler.py", line 92, in next
    batches = [self.get_data()]
  File "/home/accts/ahc49/.local/lib/python3.10/site-packages/ray/rllib/evaluation/sampler.py", line 285, in get_data
    item = next(self._env_runner)
  File "/home/accts/ahc49/.local/lib/python3.10/site-packages/ray/rllib/evaluation/sampler.py", line 671, in _env_runner
    active_envs, to_eval, outputs = _process_observations(
  File "/home/accts/ahc49/.local/lib/python3.10/site-packages/ray/rllib/evaluation/sampler.py", line 1030, in _process_observations
    ma_sample_batch = sample_collector.postprocess_episode(
  File "/home/accts/ahc49/.local/lib/python3.10/site-packages/ray/rllib/evaluation/collectors/simple_list_collector.py", line 493, in postprocess_episode
    raise ValueError(
ValueError: ('Batches sent to postprocessing must only contain steps from a single trajectory.', SampleBatch(11: ['obs', 'new_obs', 'actions', 'rewards', 'dones', 'infos', 't', 'eps_id', 'unroll_id', 'agent_index', 'vf_preds', 'action_dist_inputs', 'action_logp']))
