Failure # 1 (occurred at 2022-12-14_14-42-35)
[36mray::PPO.train()[39m (pid=1104463, ip=128.36.108.32, repr=PPO)
  File "/home/accts/ahc49/.local/lib/python3.10/site-packages/ray/tune/trainable/trainable.py", line 355, in train
    raise skipped from exception_cause(skipped)
  File "/home/accts/ahc49/.local/lib/python3.10/site-packages/ray/tune/trainable/trainable.py", line 352, in train
    result = self.step()
  File "/home/accts/ahc49/.local/lib/python3.10/site-packages/ray/rllib/algorithms/algorithm.py", line 772, in step
    results, train_iter_ctx = self._run_one_training_iteration()
  File "/home/accts/ahc49/.local/lib/python3.10/site-packages/ray/rllib/algorithms/algorithm.py", line 2953, in _run_one_training_iteration
    num_recreated += self.try_recover_from_step_attempt(
  File "/home/accts/ahc49/.local/lib/python3.10/site-packages/ray/rllib/algorithms/algorithm.py", line 2617, in try_recover_from_step_attempt
    raise error
  File "/home/accts/ahc49/.local/lib/python3.10/site-packages/ray/rllib/algorithms/algorithm.py", line 2948, in _run_one_training_iteration
    results = self.training_step()
  File "/home/accts/ahc49/.local/lib/python3.10/site-packages/ray/rllib/algorithms/ppo/ppo.py", line 408, in training_step
    train_batch = synchronous_parallel_sample(
  File "/home/accts/ahc49/.local/lib/python3.10/site-packages/ray/rllib/execution/rollout_ops.py", line 100, in synchronous_parallel_sample
    sample_batches = ray.get(
ray.exceptions.RayTaskError(ValueError): [36mray::RolloutWorker.sample()[39m (pid=1104697, ip=128.36.108.32, repr=<ray.rllib.evaluation.rollout_worker.RolloutWorker object at 0x7fec20b40c40>)
  File "/home/accts/ahc49/.local/lib/python3.10/site-packages/ray/rllib/evaluation/rollout_worker.py", line 828, in sample
    batches = [self.input_reader.next()]
  File "/home/accts/ahc49/.local/lib/python3.10/site-packages/ray/rllib/evaluation/sampler.py", line 92, in next
    batches = [self.get_data()]
  File "/home/accts/ahc49/.local/lib/python3.10/site-packages/ray/rllib/evaluation/sampler.py", line 285, in get_data
    item = next(self._env_runner)
  File "/home/accts/ahc49/.local/lib/python3.10/site-packages/ray/rllib/evaluation/sampler.py", line 694, in _env_runner
    eval_results = _do_policy_eval(
  File "/home/accts/ahc49/.local/lib/python3.10/site-packages/ray/rllib/evaluation/sampler.py", line 1207, in _do_policy_eval
    eval_results[policy_id] = policy.compute_actions_from_input_dict(
  File "/home/accts/ahc49/.local/lib/python3.10/site-packages/ray/rllib/policy/torch_policy_v2.py", line 489, in compute_actions_from_input_dict
    return self._compute_action_helper(
  File "/home/accts/ahc49/.local/lib/python3.10/site-packages/ray/rllib/utils/threading.py", line 24, in wrapper
    return func(self, *a, **k)
  File "/home/accts/ahc49/.local/lib/python3.10/site-packages/ray/rllib/policy/torch_policy_v2.py", line 1040, in _compute_action_helper
    action_dist = dist_class(dist_inputs, self.model)
  File "/home/accts/ahc49/.local/lib/python3.10/site-packages/ray/rllib/models/torch/torch_action_dist.py", line 512, in __init__
    self.flat_child_distributions = tree.map_structure(
  File "/home/accts/ahc49/.local/lib/python3.10/site-packages/tree/__init__.py", line 430, in map_structure
    [func(*args) for args in zip(*map(flatten, structures))])
  File "/home/accts/ahc49/.local/lib/python3.10/site-packages/tree/__init__.py", line 430, in <listcomp>
    [func(*args) for args in zip(*map(flatten, structures))])
  File "/home/accts/ahc49/.local/lib/python3.10/site-packages/ray/rllib/models/torch/torch_action_dist.py", line 513, in <lambda>
    lambda dist, input_: dist(input_, model),
  File "/home/accts/ahc49/.local/lib/python3.10/site-packages/ray/rllib/models/torch/torch_action_dist.py", line 73, in __init__
    self.dist = torch.distributions.categorical.Categorical(logits=self.inputs)
  File "/home/accts/ahc49/.local/lib/python3.10/site-packages/torch/distributions/categorical.py", line 66, in __init__
    super(Categorical, self).__init__(batch_shape, validate_args=validate_args)
  File "/home/accts/ahc49/.local/lib/python3.10/site-packages/torch/distributions/distribution.py", line 56, in __init__
    raise ValueError(
ValueError: Expected parameter logits (Tensor of shape (5, 5)) of distribution Categorical(logits: torch.Size([5, 5])) to satisfy the constraint IndependentConstraint(Real(), 1), but found invalid values:
tensor([[0., 0., 0., 0., 0.],
        [0., 0., 0., 0., 0.],
        [0., 0., 0., 0., 0.],
        [nan, nan, nan, nan, nan],
        [nan, nan, nan, nan, nan]])
